2024-07-04 12:12:40,135 - instabot version: 0.117.0 (bot) - INFO - Instabot version: 0.117.0 Started
2024-07-04 12:12:40,135 - instabot version: 0.117.0 (bot) - DEBUG - Bot imported from C:\Users\mechanic rayane\Desktop\instagram_bot\Insta_DM_Project\.venv\Lib\site-packages\instabot\bot\bot.py
2024-07-04 12:12:40,136 - instabot version: 0.117.0 (api_login) - INFO - Not yet logged in starting: PRE-LOGIN FLOW!
2024-07-04 12:12:40,147 - instabot version: 0.117.0 (api) - WARNING - HTTPSConnectionPool(host='i.instagram.com', port=443): Max retries exceeded with url: /api/v1/accounts/get_prefill_candidates/ (Caused by NameResolutionError("<urllib3.connection.HTTPSConnection object at 0x000002DABA508A50>: Failed to resolve 'i.instagram.com' ([Errno 11001] getaddrinfo failed)"))
2024-07-04 12:12:40,150 - instabot version: 0.117.0 (api) - WARNING - HTTPSConnectionPool(host='i.instagram.com', port=443): Max retries exceeded with url: /api/v1/qe/sync/ (Caused by NameResolutionError("<urllib3.connection.HTTPSConnection object at 0x000002DABA50AF50>: Failed to resolve 'i.instagram.com' ([Errno 11001] getaddrinfo failed)"))
2024-07-04 12:12:40,152 - instabot version: 0.117.0 (api) - WARNING - HTTPSConnectionPool(host='i.instagram.com', port=443): Max retries exceeded with url: /api/v1/launcher/sync/ (Caused by NameResolutionError("<urllib3.connection.HTTPSConnection object at 0x000002DABA5153D0>: Failed to resolve 'i.instagram.com' ([Errno 11001] getaddrinfo failed)"))
2024-07-04 12:12:40,155 - instabot version: 0.117.0 (api) - WARNING - HTTPSConnectionPool(host='i.instagram.com', port=443): Max retries exceeded with url: /api/v1/accounts/contact_point_prefill/ (Caused by NameResolutionError("<urllib3.connection.HTTPSConnection object at 0x000002DABA517810>: Failed to resolve 'i.instagram.com' ([Errno 11001] getaddrinfo failed)"))
