2024-07-03 20:52:04,365 - instabot version: 0.117.0 (bot) - INFO - Instabot version: 0.117.0 Started
2024-07-03 20:52:04,365 - instabot version: 0.117.0 (bot) - DEBUG - Bot imported from C:\Users\mechanic rayane\Desktop\instagram_bot\Insta_DM_Project\.venv\Lib\site-packages\instabot\bot\bot.py
2024-07-03 20:52:04,366 - instabot version: 0.117.0 (api_login) - INFO - Not yet logged in starting: PRE-LOGIN FLOW!
2024-07-03 20:52:04,379 - instabot version: 0.117.0 (api) - WARNING - HTTPSConnectionPool(host='i.instagram.com', port=443): Max retries exceeded with url: /api/v1/accounts/get_prefill_candidates/ (Caused by NameResolutionError("<urllib3.connection.HTTPSConnection object at 0x000001AD1FD689D0>: Failed to resolve 'i.instagram.com' ([Errno 11001] getaddrinfo failed)"))
2024-07-03 20:52:04,383 - instabot version: 0.117.0 (api) - WARNING - HTTPSConnectionPool(host='i.instagram.com', port=443): Max retries exceeded with url: /api/v1/qe/sync/ (Caused by NameResolutionError("<urllib3.connection.HTTPSConnection object at 0x000001AD1FD6AF10>: Failed to resolve 'i.instagram.com' ([Errno 11001] getaddrinfo failed)"))
2024-07-03 20:52:04,386 - instabot version: 0.117.0 (api) - WARNING - HTTPSConnectionPool(host='i.instagram.com', port=443): Max retries exceeded with url: /api/v1/launcher/sync/ (Caused by NameResolutionError("<urllib3.connection.HTTPSConnection object at 0x000001AD1FD71390>: Failed to resolve 'i.instagram.com' ([Errno 11001] getaddrinfo failed)"))
2024-07-03 20:52:04,390 - instabot version: 0.117.0 (api) - WARNING - HTTPSConnectionPool(host='i.instagram.com', port=443): Max retries exceeded with url: /api/v1/accounts/contact_point_prefill/ (Caused by NameResolutionError("<urllib3.connection.HTTPSConnection object at 0x000001AD1FD737D0>: Failed to resolve 'i.instagram.com' ([Errno 11001] getaddrinfo failed)"))
